Workbook

Sheet 01_Паки
A1: pack_no | B1: status | C1: new_prefix | D1: event_folder | E1: main_resource | F1: theme_short | G1: event_title_ru | H1: quest_group_title | I1: output_root_hint | J1: duration_text | K1: source_reference | L1: notes
A2: 1 | B2: проверено | C2: Adventure_4_1 | D2: Adventure_4_1 | E2: Adventure_GR_4 | F2: Сказки. Царевна-лягушка | G2: Царевна-лягушка | H2: Сказочные приключения | I2: стандартные пути Adventure/Adventure_4/Adventure_4_1 | J2: 2 дня | K2: Adventure_template / Adventure_3_Sport_9
A3: 2 | C3: Adventure_4_2 | D3: Adventure_4_2 | E3: Adventure_GR_4 | F3: Сказки. Репка | G3: Репка | H3: Сказочные приключения | I3: стандартные пути Adventure/Adventure_4/Adventure_4_2 | J3: 2 дня | K3: Adventure_template / Adventure_3_Sport_9
A4: 3 | C4: Adventure_4_3 | D4: Adventure_4_3 | E4: Adventure_GR_4 | F4: Сказки. Золотая рыбка | G4: Курочка Ряба | H4: Сказочные приключения | I4: стандартные пути Adventure/Adventure_4/Adventure_4_3 | J4: 2 дня | K4: Adventure_template / Adventure_3_Sport_9
A5: 4 | C5: Adventure_4_4 | D5: Adventure_4_4 | E5: Adventure_GR_4 | F5: Сказки. Волк и семеро козлят | G5: Золотая рыбка | H5: Сказочные приключения | I5: стандартные пути Adventure/Adventure_4/Adventure_4_4 | J5: 2 дня | K5: Adventure_template / Adventure_3_Sport_9
A6: 5 | C6: Adventure_4_5 | D6: Adventure_4_5 | E6: Adventure_GR_4 | F6: Сказки. Петушок золотой гребешок | G6: Волк и семеро козлят | H6: Сказочные приключения | I6: стандартные пути Adventure/Adventure_4/Adventure_4_5 | J6: 2 дня | K6: Adventure_template / Adventure_3_Sport_9
A7: 6 | C7: Adventure_4_6 | D7: Adventure_4_6 | E7: Adventure_GR_4 | F7: Сказки. Красная шапочка | G7: Петушок золотой гребешок | H7: Сказочные приключения | I7: стандартные пути Adventure/Adventure_4/Adventure_4_6 | J7: 2 дня | K7: Adventure_template / Adventure_3_Sport_9
A8: 7 | C8: Adventure_4_7 | D8: Adventure_4_7 | E8: Adventure_GR_4 | F8: Сказки. Три поросёнка | G8: Красная шапочка | H8: Сказочные приключения | I8: стандартные пути Adventure/Adventure_4/Adventure_4_7 | J8: 2 дня | K8: Adventure_template / Adventure_3_Sport_9
A9: 8 | C9: Adventure_4_8 | D9: Adventure_4_8 | E9: Adventure_GR_4 | F9: Сказки. Мартышка и очки | G9: Три поросёнка | H9: Сказочные приключения | I9: стандартные пути Adventure/Adventure_4/Adventure_4_8 | J9: 2 дня | K9: Adventure_template / Adventure_3_Sport_9
A10: 9 | C10: Adventure_4_9 | D10: Adventure_4_9 | E10: Adventure_GR_4 | F10: Сказки. Лиса и медведь | G10: Мартышка и очки | H10: Сказочные приключения | I10: стандартные пути Adventure/Adventure_4/Adventure_4_9 | J10: 2 дня | K10: Adventure_template / Adventure_3_Sport_9
A11: 10 | C11: Adventure_4_10 | D11: Adventure_4_10 | E11: Adventure_GR_4 | F11: Сказки. Лиса и медведь | G11: Лиса и медведь | H11: Сказочные приключения | I11: стандартные пути Adventure/Adventure_4/Adventure_4_10 | J11: 2 дня | K11: Adventure_template / Adventure_3_Sport_9
A12: 11 | C12: Adventure_4_11 | D12: Adventure_4_11 | E12: Adventure_GR_4 | F12: Сказки. Снежная королева | G12: Снежная королева | H12: Сказочные приключения | I12: стандартные пути Adventure/Adventure_4/Adventure_4_11 | J12: 2 дня | K12: Adventure_template / Adventure_3_Sport_9
A13: 12 | C13: Adventure_4_12 | D13: Adventure_4_12 | E13: Adventure_GR_4 | F13: Сказки. Зайчушкина избушка | G13: Зайчушкина избушка | H13: Сказочные приключения | I13: стандартные пути Adventure/Adventure_4/Adventure_4_12 | J13: 2 дня | K13: Adventure_template / Adventure_3_Sport_9
A16: Пояснения к 01_Паки
A17: new_prefix | B17: Главный classname нового набора. Это базовая замена вместо Adventure_3_Sport_9.
A18: event_folder | B18: Папка/рамка события без номера набора. Для донора Adventure_3_Sport, для нового может быть Adventure_4_Cooking.
A19: main_resource | B19: Ресурс прогресса, который игрок копит в Adventure. Для донора Adventure_GR_3 / Факел.
A20: theme_short | B20: Не техническое поле. Просто краткая тема для ИИ: спорт, кухня, сад, тени дерева и т.п.
A21: event_title_ru | B21: Видимое название rewards quest или события, например Спортивный турнир.
A22: quest_group_title | B22: Title quest_group, например Спортивные приключения.
A23: output_root_hint | B23: Опциональная подсказка по путям. Если пусто, я строю пути из event_folder/new_prefix.
A24: duration_text | B24: Текстовая длительность для rule window: 2 дня, 3 дня и т.п.

Sheet 02_Замены
A1: pack_no | B1: enabled | C1: find | D1: replace | E1: scope | F1: why / notes
A2: 1 | B2: да | C2: Adventure_3_Sport_9 | D2: Adventure_4_1 | E2: all | F2: Главный prefix/classname. Для нового pack replace будет новым prefix.
A3: 1 | B3: да | C3: Adventure_3_Sport | D3: Adventure_3_Sport | E3: paths/event_frame | F3: Папка события и event_frame.
A4: 1 | B4: да | C4: Adventure_GR_3 | D4: Adventure_GR_3 | E4: quest/rewards | F4: Главный ресурс прогресса: Факел.
A5: 1 | B5: да | C5: Pet17_Sport_9 | D5: Pet17_Adventure_4_1 | E5: pet/reward strings | F5: Pet classname, есть в финальной награде rewards quest.
A6: 1 | B6: да | C6: TrophyPet17_Sport_9 | D6: TrophyPet17_Adventure_4_1 | E6: collection_item/trophy | F6: Медалька/достижение pet.
A7: 1 | B7: нет | E7: extra | F7: Пустая строка под дополнительный replace, если всплывёт общий classname.
A8: 2 | B8: да | C8: Adventure_3_Sport_9 | D8: ='01_Паки'!C3 -> Adventure_4_2 | E8: all | F8: Главный prefix/classname набора
A9: 2 | B9: да | C9: Adventure_3_Sport | D9: ='01_Паки'!D3 -> Adventure_4_2 | E9: paths/event_frame | F9: Папка события
A10: 2 | B10: да | C10: Adventure_GR_3 | D10: ='01_Паки'!E3 -> Adventure_GR_4 | E10: quest/rewards | F10: Главный ресурс прогресса
A11: 2 | C11: Pet17_Sport_9 | D11: Pet17_Adventure_4_2 | E11: pet/reward strings | F11: Заполни, если новый pet classname не очевиден из объектов
A12: 2 | C12: TrophyPet17_Sport_9 | D12: TrophyPet17_Adventure_4_2 | E12: collection_item/trophy | F12: Заполни, если меняется trophy pet classname
A13: 2 | E13: extra | F13: Дополнительная замена, если в доноре всплывает общий classname
A14: 3 | B14: да | C14: Adventure_3_Sport_9 | D14: ='01_Паки'!C4 -> Adventure_4_3 | E14: all | F14: Главный prefix/classname набора
A15: 3 | B15: да | C15: Adventure_3_Sport | D15: ='01_Паки'!D4 -> Adventure_4_3 | E15: paths/event_frame | F15: Папка события
A16: 3 | B16: да | C16: Adventure_GR_3 | D16: ='01_Паки'!E4 -> Adventure_GR_4 | E16: quest/rewards | F16: Главный ресурс прогресса
A17: 3 | C17: Pet17_Sport_9 | D17: Pet17_Adventure_4_3 | E17: pet/reward strings | F17: Заполни, если новый pet classname не очевиден из объектов
A18: 3 | C18: TrophyPet17_Sport_9 | D18: TrophyPet17_Adventure_4_3 | E18: collection_item/trophy | F18: Заполни, если меняется trophy pet classname
A19: 3 | E19: extra | F19: Дополнительная замена, если в доноре всплывает общий classname
A20: 4 | B20: да | C20: Adventure_3_Sport_9 | D20: ='01_Паки'!C5 -> Adventure_4_4 | E20: all | F20: Главный prefix/classname набора
A21: 4 | B21: да | C21: Adventure_3_Sport | D21: ='01_Паки'!D5 -> Adventure_4_4 | E21: paths/event_frame | F21: Папка события
A22: 4 | B22: да | C22: Adventure_GR_3 | D22: ='01_Паки'!E5 -> Adventure_GR_4 | E22: quest/rewards | F22: Главный ресурс прогресса
A23: 4 | C23: Pet17_Sport_9 | D23: Pet17_Adventure_4_4 | E23: pet/reward strings | F23: Заполни, если новый pet classname не очевиден из объектов
A24: 4 | C24: TrophyPet17_Sport_9 | D24: TrophyPet17_Adventure_4_4 | E24: collection_item/trophy | F24: Заполни, если меняется trophy pet classname
A25: 4 | E25: extra | F25: Дополнительная замена, если в доноре всплывает общий classname
A26: 5 | B26: да | C26: Adventure_3_Sport_9 | D26: ='01_Паки'!C6 -> Adventure_4_5 | E26: all | F26: Главный prefix/classname набора
A27: 5 | B27: да | C27: Adventure_3_Sport | D27: ='01_Паки'!D6 -> Adventure_4_5 | E27: paths/event_frame | F27: Папка события
A28: 5 | B28: да | C28: Adventure_GR_3 | D28: ='01_Паки'!E6 -> Adventure_GR_4 | E28: quest/rewards | F28: Главный ресурс прогресса
A29: 5 | C29: Pet17_Sport_9 | D29: Pet17_Adventure_4_5 | E29: pet/reward strings | F29: Заполни, если новый pet classname не очевиден из объектов
A30: 5 | C30: TrophyPet17_Sport_9 | D30: TrophyPet17_Adventure_4_5 | E30: collection_item/trophy | F30: Заполни, если меняется trophy pet classname
A31: 5 | E31: extra | F31: Дополнительная замена, если в доноре всплывает общий classname
A32: 6 | B32: да | C32: Adventure_3_Sport_9 | D32: ='01_Паки'!C7 -> Adventure_4_6 | E32: all | F32: Главный prefix/classname набора
A33: 6 | B33: да | C33: Adventure_3_Sport | D33: ='01_Паки'!D7 -> Adventure_4_6 | E33: paths/event_frame | F33: Папка события
A34: 6 | B34: да | C34: Adventure_GR_3 | D34: ='01_Паки'!E7 -> Adventure_GR_4 | E34: quest/rewards | F34: Главный ресурс прогресса
A35: 6 | C35: Pet17_Sport_9 | D35: Pet17_Adventure_4_6 | E35: pet/reward strings | F35: Заполни, если новый pet classname не очевиден из объектов
A36: 6 | C36: TrophyPet17_Sport_9 | D36: TrophyPet17_Adventure_4_6 | E36: collection_item/trophy | F36: Заполни, если меняется trophy pet classname
A37: 6 | E37: extra | F37: Дополнительная замена, если в доноре всплывает общий classname
A38: 7 | B38: да | C38: Adventure_3_Sport_9 | D38: ='01_Паки'!C8 -> Adventure_4_7 | E38: all | F38: Главный prefix/classname набора
A39: 7 | B39: да | C39: Adventure_3_Sport | D39: ='01_Паки'!D8 -> Adventure_4_7 | E39: paths/event_frame | F39: Папка события
A40: 7 | B40: да | C40: Adventure_GR_3 | D40: ='01_Паки'!E8 -> Adventure_GR_4 | E40: quest/rewards | F40: Главный ресурс прогресса
...

Sheet 03_Объекты
A1: pack_no | B1: entity_kind | C1: reference_classname | D1: new_classname | E1: title | F1: description | G1: default_name | H1: title_attention / hint | I1: subgroup | J1: price | K1: currency | L1: extra_json_or_notes
A2: 1 | B2: main_resource | C2: Adventure_GR_3 | D2: Adventure_GR_4 | E2: Сказочка | I2: quest_resource | L2: is_hidden=1; inventory_section=constructor; id=81706
A3: 1 | B3: pet | C3: Pet17_Sport_9 | D3: Pet17_Adventure_4_1 | E3: Лягушка | F3: Эта очаровательная зелёная принцесса знает толк в волшебстве и королевских приключениях! Любое болото превратится в сказочное царство, а заветное желание обязательно исполнится! | G3: Царевна | H3: Уникальный крохонька. Можно получить только в Сказочных приключениях. | I3: pet17 | J3: open_price=money_alt=30000 | L3: event_frame=Adventure_4; feed_price=asset=Philtre:1; title_feed=От 100% до 0% Сытость падает за 3д. Одно кормление прибавляет 80% Сытости.
A4: 1 | B4: collection_item | C4: TrophyPet17_Sport_9 | D4: TrophyPet17_Adventure_4_1 | E4: Медалька "Лягушка" | F4: Раз в день можно получить бонус. | L4: rand_reward.one_of=[{"xp":600,"p":38},{"xp":1200,"p":33},{"asset":"DomovoySpeedModifier_12h","amount":1,"p":20},{"asset":"Philtre","amount":1,"p":5},{"money":1,"p":4}]
A5: 1 | B5: furniture | C5: Adventure_3_Sport_Reward_9 | D5: Adventure_4_1_Reward_1 | E5: Целуй | F5: Царевна требует внимания! | I5: big | J5: 9 | K5: money | L5: inventory_section=big;
A6: 1 | B6: pot_multi | C6: Adventure_3_Sport_Pot_Multi_9 | D6: Adventure_4_1_Pot_Multi_1 | E6: Мечта хозяюшки "Царевна лягушка" | F6: Горшочек сочный любимый. Выращивай в нём по 5 цветов за раз! | I6: multiflower | J6: 30 | K6: money
A7: 1 | B7: pot_multi_magic | C7: Adventure_3_Sport_Pot_Multi_Magic_9 | D7: Adventure_4_1_Pot_Multi_Magic | E7: Волшебная мечта хозяюшки "Болотное царство" | F7: В этом горшочке вся красота болотного царства, выращивай сразу 5 волшебных цветочков! | I7: multimagic | J7: 50 | K7: money
A8: 1 | B8: trophy | C8: TrophyPet17_Sport_9 | D8: TrophyPet17_Adventure_4_1 | E8: Лягушка | L8: quest/trophy; find=replace=TrophyPet17_Sport_9
A9: 1 | B9: box_1 | C9: Adventure_3_Sport_Box_1 | D9: Adventure_4_Box_1 | E9: Коробка с подарками | F9: Содержит волшебную синюю жабу, дающую грошики раз в день. | J9: 1 | K9: money_alt | L9: meta_info=plan=first; rand_reward={"all":[{"asset":"MoneyboxFrogBlue","amount":1},{"asset":"Shop_of_miracles_GR_1","amount":20}]}
A10: 1 | B10: box_2 | C10: Adventure_3_Sport_Box_2 | D10: Adventure_4_Box_2 | E10: Коробка с подарками | F10: Содержит: 2 бустера для мгновенной уборки мусора со всех горшков в локации, 15 оживителей, 15 ускорителей, 20 жетонов | J10: 1 | K10: money_alt | L10: meta_info=plan=first; rand_reward={"all":[{"asset":"Stuff_Booster_CleanPot","amount":2},{"asset":"RecoverPlantBooster","amount":15},{"asset":"AccelerationPlantBooster","amount":15},{"asset":"AccelerateCraftingBooster","amount":20},{"asset":"Shop_of_miracles_GR_1","amount":30}]}
A11: 1 | B11: box_3 | C11: Adventure_3_Sport_Box_3 | D11: Adventure_4_Box_3 | E11: Коробка с подарками | F11: Коробка содержит: 4 бустеров для мгновенной уборки мусора со всех горшков в локации, 20 оживителей, 20 ускорителей, 30 жетонов | J11: 1 | K11: money_alt | L11: meta_info=plan=first; rand_reward={"all":[{"asset":"Stuff_Booster_CleanPot","amount":4},{"asset":"RecoverPlantBooster","amount":20},{"asset":"AccelerationPlantBooster","amount":20},{"asset":"AccelerateCraftingBooster","amount":30},{"asset":"Shop_of_miracles_GR_1","amount":50}]}
A12: 2 | B12: main_resource | C12: Adventure_GR_3 | D12: Adventure_GR_4 | E12: Сказочка | I12: quest_resource | L12: is_hidden=1; inventory_section=constructor; id=81706
A13: 2 | B13: pet | C13: Pet17_Sport_9 | D13: Pet17_Adventure_4_2 | E13: Мышка | F13: Эта очаровательная зелёная принцесса знает толк в волшебстве и королевских приключениях! Любое болото превратится в сказочное царство, а заветное желание обязательно исполнится! | G13: Нарушка | H13: Уникальный крохонька. Можно получить только в Сказочных приключениях. | I13: pet17 | J13: open_price=money_alt=30000 | L13: event_frame=Adventure_4; feed_price=asset=FeltToy:1; title_feed=От 100% до 0% Сытость падает за 3д. Одно кормление прибавляет 80% Сытости.
A14: 2 | B14: collection_item | C14: TrophyPet17_Sport_9 | D14: TrophyPet17_Adventure_4_2 | E14: Медалька "Мышка" | F14: Раз в день можно получить бонус. | L14: rand_reward.one_of=[{"xp":600,"p":38},{"xp":1200,"p":33},{"asset":"DomovoySpeedModifier_12h","amount":1,"p":20},{"asset":"FeltToy","amount":1,"p":5},{"money":1,"p":4}]
A15: 2 | B15: furniture | C15: Adventure_3_Sport_Reward_9 | D15: Adventure_4_2_Reward_1 | E15: Декор "Тянем-потянем" | F15: Командная работа! | I15: big | J15: 9 | K15: money | L15: inventory_section=big;
A16: 2 | B16: pot_multi | C16: Adventure_3_Sport_Pot_Multi_9 | D16: Adventure_4_2_Pot_Multi_1 | E16: Мечта хозяюшки "Репка" | F16: Горшочек сочный любимый. Выращивай в нём по 5 цветов за раз! | I16: multiflower | J16: 30 | K16: money
A17: 2 | B17: pot_multi_magic | C17: Adventure_3_Sport_Pot_Multi_Magic_9 | D17: Adventure_4_2_Pot_Multi_Magic | E17: Волшебная мечта хозяюшки "Репка" | F17: Тянули, тянули и вытащили репку! Выращивай сразу 5 волшебных цветочков! | I17: multimagic | J17: 50 | K17: money
A18: 2 | B18: trophy | C18: TrophyPet17_Sport_9 | D18: TrophyPet17_Adventure_4_2 | E18: Мышка | L18: quest/trophy; find=replace=TrophyPet17_Sport_9
A19: 2 | B19: box_1 | C19: Adventure_3_Sport_Box_1 | D19: Adventure_4_Box_1 | E19: Коробка с подарками | F19: Содержит волшебную синюю жабу, дающую грошики раз в день. | J19: 1 | K19: money_alt | L19: meta_info=plan=first; rand_reward={"all":[{"asset":"MoneyboxFrogBlue","amount":1},{"asset":"Shop_of_miracles_GR_1","amount":20}]}
A20: 2 | B20: box_2 | C20: Adventure_3_Sport_Box_2 | D20: Adventure_4_Box_2 | E20: Коробка с подарками | F20: Содержит: 2 бустера для мгновенной уборки мусора со всех горшков в локации, 15 оживителей, 15 ускорителей, 20 жетонов | J20: 1 | K20: money_alt | L20: meta_info=plan=first; rand_reward={"all":[{"asset":"Stuff_Booster_CleanPot","amount":2},{"asset":"RecoverPlantBooster","amount":15},{"asset":"AccelerationPlantBooster","amount":15},{"asset":"AccelerateCraftingBooster","amount":20},{"asset":"Shop_of_miracles_GR_1","amount":30}]}
A21: 2 | B21: box_3 | C21: Adventure_3_Sport_Box_3 | D21: Adventure_4_Box_3 | E21: Коробка с подарками | F21: Коробка содержит: 4 бустеров для мгновенной уборки мусора со всех горшков в локации, 20 оживителей, 20 ускорителей, 30 жетонов | J21: 1 | K21: money_alt | L21: meta_info=plan=first; rand_reward={"all":[{"asset":"Stuff_Booster_CleanPot","amount":4},{"asset":"RecoverPlantBooster","amount":20},{"asset":"AccelerationPlantBooster","amount":20},{"asset":"AccelerateCraftingBooster","amount":30},{"asset":"Shop_of_miracles_GR_1","amount":50}]}
A22: 3 | B22: main_resource | C22: Adventure_GR_3 | D22: Adventure_GR_4 | E22: Сказочка | I22: quest_resource | L22: is_hidden=1; inventory_section=constructor; id=81706
A23: 3 | B23: pet | C23: Pet17_Sport_9 | D23: Pet17_Adventure_4_3 | E23: Цыпленок | F23: Этот любопытный цыплёнок — настоящий охотник за чудесами! С увеличительным стеклом и вместительным фартуком он исследует каждый уголок в поисках редких находок. А золотое яйцо в его лапках доказывает: если рядом Золотко — сокровище обязательно найдётся! | G23: Золотко | H23: Уникальный крохонька. Можно получить только в Сказочных приключениях. | I23: pet17 | J23: open_price=money_alt=30000 | L23: event_frame=Adventure_4; feed_price=asset=BagOfFlour:1; title_feed=От 100% до 0% Сытость падает за 3д. Одно кормление прибавляет 80% Сытости.
A24: 3 | B24: collection_item | C24: TrophyPet17_Sport_9 | D24: TrophyPet17_Adventure_4_3 | E24: Медалька "Цыпленок" | F24: Раз в день можно получить бонус. | L24: rand_reward.one_of=[{"xp":600,"p":38},{"xp":1200,"p":33},{"asset":"DomovoySpeedModifier_12h","amount":1,"p":20},{"asset":"BagOfFlour","amount":1,"p":5},{"money":1,"p":4}]
A25: 3 | B25: furniture | C25: Adventure_3_Sport_Reward_9 | D25: Adventure_4_3_Reward_1 | E25: Декор "Курочка-Ряба" | F25: Бизнес пойдёт в гору! | I25: big | J25: 9 | K25: money | L25: inventory_section=big;
A26: 3 | B26: pot_multi | C26: Adventure_3_Sport_Pot_Multi_9 | D26: Adventure_4_3_Pot_Multi_1 | E26: Мечта хозяюшки "Курочка-Ряба" | F26: Горшочек сочный любимый. Выращивай в нём по 5 цветов за раз! | I26: multiflower | J26: 30 | K26: money
A27: 3 | B27: pot_multi_magic | C27: Adventure_3_Sport_Pot_Multi_Magic_9 | D27: Adventure_4_3_Pot_Multi_Magic | E27: Волшебная мечта хозяюшки "Золотое яйцо" | F27: Новый горшочек проклюнулся, скорее сажай в него цветы! Выращивай сразу 5 волшебных цветочков! | I27: multimagic | J27: 50 | K27: money
A28: 3 | B28: trophy | C28: TrophyPet17_Sport_9 | D28: TrophyPet17_Adventure_4_3 | E28: Цыпленок | L28: quest/trophy; find=replace=TrophyPet17_Sport_9
A29: 3 | B29: box_1 | C29: Adventure_3_Sport_Box_1 | D29: Adventure_4_Box_1 | E29: Коробка с подарками | F29: Содержит волшебную синюю жабу, дающую грошики раз в день. | J29: 1 | K29: money_alt | L29: meta_info=plan=first; rand_reward={"all":[{"asset":"MoneyboxFrogBlue","amount":1},{"asset":"Shop_of_miracles_GR_1","amount":20}]}
A30: 3 | B30: box_2 | C30: Adventure_3_Sport_Box_2 | D30: Adventure_4_Box_2 | E30: Коробка с подарками | F30: Содержит: 2 бустера для мгновенной уборки мусора со всех горшков в локации, 15 оживителей, 15 ускорителей, 20 жетонов | J30: 1 | K30: money_alt | L30: meta_info=plan=first; rand_reward={"all":[{"asset":"Stuff_Booster_CleanPot","amount":2},{"asset":"RecoverPlantBooster","amount":15},{"asset":"AccelerationPlantBooster","amount":15},{"asset":"AccelerateCraftingBooster","amount":20},{"asset":"Shop_of_miracles_GR_1","amount":30}]}
A31: 3 | B31: box_3 | C31: Adventure_3_Sport_Box_3 | D31: Adventure_4_Box_3 | E31: Коробка с подарками | F31: Коробка содержит: 4 бустеров для мгновенной уборки мусора со всех горшков в локации, 20 оживителей, 20 ускорителей, 30 жетонов | J31: 1 | K31: money_alt | L31: meta_info=plan=first; rand_reward={"all":[{"asset":"Stuff_Booster_CleanPot","amount":4},{"asset":"RecoverPlantBooster","amount":20},{"asset":"AccelerationPlantBooster","amount":20},{"asset":"AccelerateCraftingBooster","amount":30},{"asset":"Shop_of_miracles_GR_1","amount":50}]}
A32: 4 | B32: main_resource | C32: Adventure_GR_3 | D32: Adventure_GR_4 | E32: Сказочка | I32: quest_resource | L32: is_hidden=1; inventory_section=constructor; id=81706
A33: 4 | B33: pet | C33: Pet17_Sport_9 | D33: Pet17_Adventure_4_4 | E33: Рыбка | F33: Настоящая принцесса подводного царства! В нарядном голубом платье и золотой короне она исполняет добрые желания и приносит удачу. | G33: Злата | H33: Уникальный крохонька. Можно получить только в Сказочных приключениях. | I33: pet17 | J33: open_price=money_alt=30000 | L33: event_frame=Adventure_4; feed_price=asset=Boglaz:1; title_feed=От 100% до 0% Сытость падает за 3д. Одно кормление прибавляет 80% Сытости.
A34: 4 | B34: collection_item | C34: TrophyPet17_Sport_9 | D34: TrophyPet17_Adventure_4_4 | E34: Медалька "Рыбка" | F34: Раз в день можно получить бонус. | L34: rand_reward.one_of=[{"xp":600,"p":38},{"xp":1200,"p":33},{"asset":"DomovoySpeedModifier_12h","amount":1,"p":20},{"asset":"Boglaz","amount":1,"p":5},{"money":1,"p":4}]
A35: 4 | B35: furniture | C35: Adventure_3_Sport_Reward_9 | D35: Adventure_4_4_Reward_1 | E35: Декор "Очень много желаний" | F35: Наглость - второе счастье! | I35: big | J35: 9 | K35: money | L35: inventory_section=big;
A36: 4 | B36: pot_multi | C36: Adventure_3_Sport_Pot_Multi_9 | D36: Adventure_4_4_Pot_Multi_1 | E36: Мечта хозяюшки "Золотая рыбка" | F36: Горшочек сочный любимый. Выращивай в нём по 5 цветов за раз! | I36: multiflower | J36: 30 | K36: money
A37: 4 | B37: pot_multi_magic | C37: Adventure_3_Sport_Pot_Multi_Magic_9 | D37: Adventure_4_4_Pot_Multi_Magic | E37: Волшебная мечта хозяюшки "Морская звезда" | F37: Со дна морского, а теперь у тебя! Выращивай сразу 5 волшебных цветочков! | I37: multimagic | J37: 50 | K37: money
A38: 4 | B38: trophy | C38: TrophyPet17_Sport_9 | D38: TrophyPet17_Adventure_4_4 | E38: Рыбка | L38: quest/trophy; find=replace=TrophyPet17_Sport_9
A39: 4 | B39: box_1 | C39: Adventure_3_Sport_Box_1 | D39: Adventure_4_Box_1 | E39: Коробка с подарками | F39: Содержит волшебную синюю жабу, дающую грошики раз в день. | J39: 1 | K39: money_alt | L39: meta_info=plan=first; rand_reward={"all":[{"asset":"MoneyboxFrogBlue","amount":1},{"asset":"Shop_of_miracles_GR_1","amount":20}]}
A40: 4 | B40: box_2 | C40: Adventure_3_Sport_Box_2 | D40: Adventure_4_Box_2 | E40: Коробка с подарками | F40: Содержит: 2 бустера для мгновенной уборки мусора со всех горшков в локации, 15 оживителей, 15 ускорителей, 20 жетонов | J40: 1 | K40: money_alt | L40: meta_info=plan=first; rand_reward={"all":[{"asset":"Stuff_Booster_CleanPot","amount":2},{"asset":"RecoverPlantBooster","amount":15},{"asset":"AccelerationPlantBooster","amount":15},{"asset":"AccelerateCraftingBooster","amount":20},{"asset":"Shop_of_miracles_GR_1","amount":30}]}
...

Sheet 04_Квесты
A1: pack_no | B1: quest_key | C1: reference_identifier | D1: new_identifier | E1: title | F1: description | G1: congratulation | H1: rule_window_description | I1: notes
A2: 1 | B2: main_quest | C2: Adventure_3_Sport_9_quest | D2: Adventure_4_1_quest | I2: Главный технический quest. В шаблоне меняется identifier/replace, видимого title нет.
A3: 1 | B3: quest_task_1 | C3: Adventure_3_Sport_9_quest_task_1 | D3: Adventure_4_1_quest_task_1 | I3: Задача 1 основного adventure quest. Видимые поля наследуются из донора.
A4: 1 | B4: quest_task_2 | C4: Adventure_3_Sport_9_quest_task_2 | D4: Adventure_4_1_quest_task_2 | I4: Задача 2 основного adventure quest. Видимые поля наследуются из донора.
A5: 1 | B5: quest_task_3 | C5: Adventure_3_Sport_9_quest_task_3 | D5: Adventure_4_1_quest_task_3 | I5: Задача 3 основного adventure quest. Видимые поля наследуются из донора.
A6: 1 | B6: rewards_quest | C6: Adventure_3_Sport_9_rewards | D6: Adventure_4_1_rewards | E6: Adventure_4_1 | G6: Сказочный турнир | I6: Шапка rewards quest. Сами milestones лежат на 05_Награды.
A7: 1 | B7: quest_group | C7: Adventure_3_Sport_9 | D7: Adventure_4_1 | E7: Сказочные приключения | H7: Сказочные соревнования - это особое событие, в котором требуется выполнять задания за ограниченное время. Кроме выполнения, любое задание можно сбросить, тогда оно исчезнет. В обоих случаях нужно подождать 30 минут, чтобы получить новое задание. А если выполнить все 3 задания, то мгновенно появятся 3 новых! Выполняя задания, ты получаешь Сказочки, а набрав нужное количество, получишь награду и будешь двигаться к следующей. Среди наград - сказочный декор, волшебство, волшебная жаба, волшебные сказочные горшочки, а главный приз - новый уникальный крохонька! Не теряйте времени! У вас есть всего 2 дня чтобы получить все награды, удачи! | I7: Quest group window/rules. Тут особенно важно убрать старую тему из текста правил.
A8: 2 | B8: main_quest | C8: Adventure_3_Sport_9_quest | D8: Adventure_4_2_quest
A9: 2 | B9: quest_task_1 | C9: Adventure_3_Sport_9_quest_task_1 | D9: Adventure_4_2_quest_task_1
A10: 2 | B10: quest_task_2 | C10: Adventure_3_Sport_9_quest_task_2 | D10: Adventure_4_2_quest_task_2
A11: 2 | B11: quest_task_3 | C11: Adventure_3_Sport_9_quest_task_3 | D11: Adventure_4_2_quest_task_3
A12: 2 | B12: rewards_quest | C12: Adventure_3_Sport_9_rewards | D12: Adventure_4_2_rewards | E12: Adventure_4_2 | G12: Сказочный турнир
A13: 2 | B13: quest_group | C13: Adventure_3_Sport_9 | D13: Adventure_4_2 | E13: Сказочные приключения | H13: Сказочные соревнования - это особое событие, в котором требуется выполнять задания за ограниченное время. Кроме выполнения, любое задание можно сбросить, тогда оно исчезнет. В обоих случаях нужно подождать 30 минут, чтобы получить новое задание. А если выполнить все 3 задания, то мгновенно появятся 3 новых! Выполняя задания, ты получаешь Сказочки, а набрав нужное количество, получишь награду и будешь двигаться к следующей. Среди наград - сказочный декор, волшебство, волшебная жаба, волшебные сказочные горшочки, а главный приз - новый уникальный крохонька! Не теряйте времени! У вас есть всего 2 дня чтобы получить все награды, удачи!
A14: 3 | B14: main_quest | C14: Adventure_3_Sport_9_quest | D14: Adventure_4_3_quest
A15: 3 | B15: quest_task_1 | C15: Adventure_3_Sport_9_quest_task_1 | D15: Adventure_4_3_quest_task_1
A16: 3 | B16: quest_task_2 | C16: Adventure_3_Sport_9_quest_task_2 | D16: Adventure_4_3_quest_task_2
A17: 3 | B17: quest_task_3 | C17: Adventure_3_Sport_9_quest_task_3 | D17: Adventure_4_3_quest_task_3
A18: 3 | B18: rewards_quest | C18: Adventure_3_Sport_9_rewards | D18: Adventure_4_3_rewards | E18: Adventure_4_3 | G18: Сказочный турнир
A19: 3 | B19: quest_group | C19: Adventure_3_Sport_9 | D19: Adventure_4_3 | E19: Сказочные приключения | H19: Сказочные соревнования - это особое событие, в котором требуется выполнять задания за ограниченное время. Кроме выполнения, любое задание можно сбросить, тогда оно исчезнет. В обоих случаях нужно подождать 30 минут, чтобы получить новое задание. А если выполнить все 3 задания, то мгновенно появятся 3 новых! Выполняя задания, ты получаешь Сказочки, а набрав нужное количество, получишь награду и будешь двигаться к следующей. Среди наград - сказочный декор, волшебство, волшебная жаба, волшебные сказочные горшочки, а главный приз - новый уникальный крохонька! Не теряйте времени! У вас есть всего 2 дня чтобы получить все награды, удачи!
A20: 4 | B20: main_quest | C20: Adventure_3_Sport_9_quest | D20: Adventure_4_4_quest
A21: 4 | B21: quest_task_1 | C21: Adventure_3_Sport_9_quest_task_1 | D21: Adventure_4_4_quest_task_1
A22: 4 | B22: quest_task_2 | C22: Adventure_3_Sport_9_quest_task_2 | D22: Adventure_4_4_quest_task_2
A23: 4 | B23: quest_task_3 | C23: Adventure_3_Sport_9_quest_task_3 | D23: Adventure_4_4_quest_task_3
A24: 4 | B24: rewards_quest | C24: Adventure_3_Sport_9_rewards | D24: Adventure_4_4_rewards | E24: Adventure_4_4 | G24: Сказочный турнир
A25: 4 | B25: quest_group | C25: Adventure_3_Sport_9 | D25: Adventure_4_4 | E25: Сказочные приключения | H25: Сказочные соревнования - это особое событие, в котором требуется выполнять задания за ограниченное время. Кроме выполнения, любое задание можно сбросить, тогда оно исчезнет. В обоих случаях нужно подождать 30 минут, чтобы получить новое задание. А если выполнить все 3 задания, то мгновенно появятся 3 новых! Выполняя задания, ты получаешь Сказочки, а набрав нужное количество, получишь награду и будешь двигаться к следующей. Среди наград - сказочный декор, волшебство, волшебная жаба, волшебные сказочные горшочки, а главный приз - новый уникальный крохонька! Не теряйте времени! У вас есть всего 2 дня чтобы получить все награды, удачи!
A26: 5 | B26: main_quest | C26: Adventure_3_Sport_9_quest | D26: Adventure_4_5_quest
A27: 5 | B27: quest_task_1 | C27: Adventure_3_Sport_9_quest_task_1 | D27: Adventure_4_5_quest_task_1
A28: 5 | B28: quest_task_2 | C28: Adventure_3_Sport_9_quest_task_2 | D28: Adventure_4_5_quest_task_2
A29: 5 | B29: quest_task_3 | C29: Adventure_3_Sport_9_quest_task_3 | D29: Adventure_4_5_quest_task_3
A30: 5 | B30: rewards_quest | C30: Adventure_3_Sport_9_rewards | D30: Adventure_4_5_rewards | E30: Adventure_4_5 | G30: Сказочный турнир
A31: 5 | B31: quest_group | C31: Adventure_3_Sport_9 | D31: Adventure_4_5 | E31: Сказочные приключения | H31: Сказочные соревнования - это особое событие, в котором требуется выполнять задания за ограниченное время. Кроме выполнения, любое задание можно сбросить, тогда оно исчезнет. В обоих случаях нужно подождать 30 минут, чтобы получить новое задание. А если выполнить все 3 задания, то мгновенно появятся 3 новых! Выполняя задания, ты получаешь Сказочки, а набрав нужное количество, получишь награду и будешь двигаться к следующей. Среди наград - сказочный декор, волшебство, волшебная жаба, волшебные сказочные горшочки, а главный приз - новый уникальный крохонька! Не теряйте времени! У вас есть всего 2 дня чтобы получить все награды, удачи!
A32: 6 | B32: main_quest | C32: Adventure_3_Sport_9_quest | D32: Adventure_4_6_quest
A33: 6 | B33: quest_task_1 | C33: Adventure_3_Sport_9_quest_task_1 | D33: Adventure_4_6_quest_task_1
A34: 6 | B34: quest_task_2 | C34: Adventure_3_Sport_9_quest_task_2 | D34: Adventure_4_6_quest_task_2
A35: 6 | B35: quest_task_3 | C35: Adventure_3_Sport_9_quest_task_3 | D35: Adventure_4_6_quest_task_3
A36: 6 | B36: rewards_quest | C36: Adventure_3_Sport_9_rewards | D36: Adventure_4_6_rewards | E36: Adventure_4_6 | G36: Сказочный турнир
A37: 6 | B37: quest_group | C37: Adventure_3_Sport_9 | D37: Adventure_4_6 | E37: Сказочные приключения | H37: Сказочные соревнования - это особое событие, в котором требуется выполнять задания за ограниченное время. Кроме выполнения, любое задание можно сбросить, тогда оно исчезнет. В обоих случаях нужно подождать 30 минут, чтобы получить новое задание. А если выполнить все 3 задания, то мгновенно появятся 3 новых! Выполняя задания, ты получаешь Сказочки, а набрав нужное количество, получишь награду и будешь двигаться к следующей. Среди наград - сказочный декор, волшебство, волшебная жаба, волшебные сказочные горшочки, а главный приз - новый уникальный крохонька! Не теряйте времени! У вас есть всего 2 дня чтобы получить все награды, удачи!
A38: 7 | B38: main_quest | C38: Adventure_3_Sport_9_quest | D38: Adventure_4_7_quest
A39: 7 | B39: quest_task_1 | C39: Adventure_3_Sport_9_quest_task_1 | D39: Adventure_4_7_quest_task_1
A40: 7 | B40: quest_task_2 | C40: Adventure_3_Sport_9_quest_task_2 | D40: Adventure_4_7_quest_task_2
...

Sheet 05_Награды
A1: pack_no | B1: task_index | C1: amount | D1: classname | E1: reward | F1: title | G1: hint | H1: congratulation | I1: identifier | J1: notes
A2: 1 | B2: 0 | C2: 500 | D2: Adventure_GR_4 | E2: asset=Adventure_4_1_Reward_1:1 | F2: Целуй | G2: Царевна требует внимания! | H2: Целуй | J2: autofilled from 03_Objects by Codex
A3: 1 | B3: 1 | C3: 1100 | D3: Adventure_GR_4 | E3: asset=DomovoySpeedModifier_12h:1 | F3: Чары "Шустрик" | G3: Увеличивает скорость передвижения домовёнка. Рекомендуется применять, если дел много, а времени мало. Действует 12 часов. | H3: Чары "Шустрик" | J3: autofilled from 03_Objects by Codex
A4: 1 | B4: 2 | C4: 1800 | D4: Adventure_GR_4 | E4: asset=Adventure_4_Box_1:1 | F4: Коробка с подарками | G4: Содержит 20 Фоминок и волшебную синюю жабу, дающую грошики раз в день. | H4: Коробка с подарками | J4: autofilled from 03_Objects by Codex
A5: 1 | B5: 3 | C5: 2500 | D5: Adventure_GR_4 | E5: asset=Adventure_4_1_Pot_Multi_1:1 | F5: Мечта хозяюшки "Царевна лягушка" | G5: Горшочек сочный любимый. Выращивай в нём по 5 цветов за раз! | H5: Мечта хозяюшки "Царевна лягушка" | J5: autofilled from 03_Objects by Codex
A6: 1 | B6: 4 | C6: 3300 | D6: Adventure_GR_4 | E6: asset=Adventure_4_Box_2:1 | F6: Коробка с подарками | G6: Содержит: 30 Фоминок, 2 бустера для мгновенной уборки мусора со всех горшков, 15 оживителей, 15 ускорителей, 20 жетонов | H6: Коробка с подарками | J6: autofilled from 03_Objects by Codex
A7: 1 | B7: 5 | C7: 4100 | D7: Adventure_GR_4 | E7: asset=Adventure_4_1_Pot_Multi_Magic:1 | F7: Волшебная мечта хозяюшки "Болотное царство" | G7: В этом горшочке вся красота болотного царства, выращивай сразу 5 волшебных цветочков! | H7: Волшебная мечта хозяюшки "Болотное царство" | J7: autofilled from 03_Objects by Codex
A8: 1 | B8: 6 | C8: 5000 | D8: Adventure_GR_4 | E8: asset=Adventure_4_Box_3:1+asset=Pet17_Adventure_4_1:1 | F8: Коробка с подарками | G8: Коробка содержит: 50 Фоминок, 4 бустера для мгновенной уборки мусора со всех горшков, 20 оживителей, 20 ускорителей, 30 жетонов.\nСупер-приз кроха "Лягушка" за достижение последней отметки | H8: Коробка с подарками + Кроха Лягушка | J8: autofilled from 03_Objects by Codex
A9: 2 | B9: 0 | C9: 500 | D9: Adventure_GR_4 | E9: asset=Adventure_4_2_Reward_1:1 | F9: Декор "Тянем-потянем" | G9: Командная работа! | H9: Декор "Тянем-потянем" | J9: autofilled from 03_Objects by Codex
A10: 2 | B10: 1 | C10: 1100 | D10: Adventure_GR_4 | E10: asset=DomovoySpeedModifier_12h:1 | F10: Чары "Шустрик" | G10: Увеличивает скорость передвижения домовёнка. Рекомендуется применять, если дел много, а времени мало. Действует 12 часов. | H10: Чары "Шустрик" | J10: autofilled from 03_Objects by Codex
A11: 2 | B11: 2 | C11: 1800 | D11: Adventure_GR_4 | E11: asset=Adventure_4_Box_1:1 | F11: Коробка с подарками | G11: Содержит 20 Фоминок и волшебную синюю жабу, дающую грошики раз в день. | H11: Коробка с подарками | J11: autofilled from 03_Objects by Codex
A12: 2 | B12: 3 | C12: 2500 | D12: Adventure_GR_4 | E12: asset=Adventure_4_2_Pot_Multi_1:1 | F12: Мечта хозяюшки "Репка" | G12: Горшочек сочный любимый. Выращивай в нём по 5 цветов за раз! | H12: Мечта хозяюшки "Репка" | J12: autofilled from 03_Objects by Codex
A13: 2 | B13: 4 | C13: 3300 | D13: Adventure_GR_4 | E13: asset=Adventure_4_Box_2:1 | F13: Коробка с подарками | G13: Содержит: 30 Фоминок, 2 бустера для мгновенной уборки мусора со всех горшков, 15 оживителей, 15 ускорителей, 20 жетонов | H13: Коробка с подарками | J13: autofilled from 03_Objects by Codex
... A85: 12 | B85: 6 | C85: 5000 | D85: Adventure_GR_4 | E85: asset=Adventure_4_Box_3:1+asset=Pet17_Adventure_4_12:1 | F85: Коробка с подарками | G85: Коробка содержит: 50 Фоминок, 4 бустера для мгновенной уборки мусора со всех горшков, 20 оживителей, 20 ускорителей, 30 жетонов.\nСупер-приз кроха "Зайчик" за достижение последней отметки | H85: Коробка с подарками + Кроха Зайчик | J85: autofilled from 03_Objects by Codex

Sheet 06_Экономика
A1: pack_no | B1: proto_family | C1: target | D1: field | E1: reference_value | F1: new_value | G1: inherit_if_blank | H1: notes
A2: 1 | B2: quest_action | C2: paid_reset_task_1 | D2: open_price | E2: money=2 | F2: money=2 | G2: нет | H2: В референсной строке new_value заполнен текущим значением. Для нового pack можно оставить пустым и наследовать.
A3: 1 | B3: quest_action | C3: paid_reset_task_2 | D3: open_price | E3: money=2 | F3: money=2 | G3: нет | H3: В референсной строке new_value заполнен текущим значением. Для нового pack можно оставить пустым и наследовать.
A4: 1 | B4: quest_action | C4: paid_reset_task_3 | D4: open_price | E4: money=2 | F4: money=2 | G4: нет | H4: В референсной строке new_value заполнен текущим значением. Для нового pack можно оставить пустым и наследовать.
A5: 1 | B5: pet | C5: pet | D5: open_price | E5: money_alt=30000 | F5: money_alt=30000 | G5: нет | H5: В референсной строке new_value заполнен текущим значением. Для нового pack можно оставить пустым и наследовать.
A6: 1 | B6: pet | C6: pet | D6: feed_price | E6: asset=BuckwheatPot:1 | F6: asset=BuckwheatPot:1 | G6: нет | H6: В референсной строке new_value заполнен текущим значением. Для нового pack можно оставить пустым и наследовать.
A7: 1 | B7: pet | C7: pet | D7: spoil_price | E7: money=5 | F7: money=5 | G7: нет | H7: В референсной строке new_value заполнен текущим значением. Для нового pack можно оставить пустым и наследовать.
A8: 1 | B8: pot | C8: pot_multi | D8: price | E8: 30 / money | F8: 30 / money | G8: нет | H8: В референсной строке new_value заполнен текущим значением. Для нового pack можно оставить пустым и наследовать.
A9: 1 | B9: pot | C9: pot_multi_magic | D9: price | E9: 50 / money | F9: 50 / money | G9: нет | H9: В референсной строке new_value заполнен текущим значением. Для нового pack можно оставить пустым и наследовать.
A10: 1 | B10: furniture | C10: reward_furniture | D10: price | E10: 9 / money | F10: 9 / money | G10: нет | H10: В референсной строке new_value заполнен текущим значением. Для нового pack можно оставить пустым и наследовать.
A11: 2 | B11: quest_action | C11: paid_reset_task_1 | D11: open_price | E11: money=2 | F11: money=2 | G11: да
A12: 2 | B12: quest_action | C12: paid_reset_task_2 | D12: open_price | E12: money=2 | F12: money=2 | G12: да
A13: 2 | B13: quest_action | C13: paid_reset_task_3 | D13: open_price | E13: money=2 | F13: money=2 | G13: да
A14: 2 | B14: pet | C14: pet | D14: open_price | E14: money_alt=30000 | F14: money_alt=30000 | G14: да
A15: 2 | B15: pet | C15: pet | D15: feed_price | E15: asset=BuckwheatPot:1 | F15: asset=BuckwheatPot:1 | G15: да
A16: 2 | B16: pet | C16: pet | D16: spoil_price | E16: money=5 | F16: money=5 | G16: да
A17: 2 | B17: pot | C17: pot_multi | D17: price | E17: 30 / money | F17: 30 / money | G17: да
A18: 2 | B18: pot | C18: pot_multi_magic | D18: price | E18: 50 / money | F18: 50 / money | G18: да
A19: 2 | B19: furniture | C19: reward_furniture | D19: price | E19: 9 / money | F19: 9 / money | G19: да
A20: 3 | B20: quest_action | C20: paid_reset_task_1 | D20: open_price | E20: money=2 | F20: money=2 | G20: да
A21: 3 | B21: quest_action | C21: paid_reset_task_2 | D21: open_price | E21: money=2 | F21: money=2 | G21: да
A22: 3 | B22: quest_action | C22: paid_reset_task_3 | D22: open_price | E22: money=2 | F22: money=2 | G22: да
... A109: 12 | B109: furniture | C109: reward_furniture | D109: price | E109: 9 / money | F109: 9 / money | G109: да

Sheet 07_Выходные файлы
A1: pack_no | B1: family | C1: final_xlsx | D1: first_sheet_must_be | E1: status | F1: notes
A2: 1 | B2: quest_item | C2: quest_item.xlsx | D2: conf | E2: сгенерировано | F2: output/Adventure_4_1_pack_tables/quest_item.xlsx
A3: 1 | B3: collection_item | C3: collection_item.xlsx | D3: conf | E3: сгенерировано | F3: output/Adventure_4_1_pack_tables/collection_item.xlsx
A4: 1 | B4: furniture | C4: furniture.xlsx | D4: conf | E4: сгенерировано | F4: output/Adventure_4_1_pack_tables/furniture.xlsx
A5: 1 | B5: pet | C5: pet.xlsx | D5: conf | E5: сгенерировано | F5: output/Adventure_4_1_pack_tables/pet.xlsx
A6: 1 | B6: pot | C6: pot.xlsx | D6: conf | E6: сгенерировано | F6: output/Adventure_4_1_pack_tables/pot.xlsx
A7: 1 | B7: mystery_box | C7: mystery_box.xlsx | D7: conf | E7: сгенерировано | F7: output/Adventure_4_1_pack_tables/mystery_box.xlsx
A8: 1 | B8: quest | C8: quest.xlsx | D8: conf | E8: сгенерировано | F8: output/Adventure_4_1_pack_tables/quest.xlsx
A9: 1 | B9: quest_action | C9: quest_action.xlsx | D9: conf | E9: сгенерировано | F9: output/Adventure_4_1_pack_tables/quest_action.xlsx
A10: 1 | B10: quest_group | C10: quest_group.xlsx | D10: conf | E10: сгенерировано | F10: output/Adventure_4_1_pack_tables/quest_group.xlsx
A11: 1 | B11: trophy | C11: trophy.xlsx | D11: conf | E11: сгенерировано | F11: output/Adventure_4_1_pack_tables/trophy.xlsx
A12: 2 | B12: quest_item | C12: quest_item.xlsx | D12: conf | E12: сгенерировано | F12: output/Adventure_4_2_pack_tables/quest_item.xlsx
A13: 2 | B13: collection_item | C13: collection_item.xlsx | D13: conf | E13: сгенерировано | F13: output/Adventure_4_2_pack_tables/collection_item.xlsx
... A121: 12 | B121: trophy | C121: trophy.xlsx | D121: conf | E121: сгенерировано | F121: output/Adventure_4_12_pack_tables/trophy.xlsx

Sheet 08_Чеклист
A1: pack_no | B1: check | C1: done | D1: notes
A2: 1 | B2: new_prefix уникален и совпадает с будущими classname | C2: да | D2: Референсная строка заполнена.
A3: 1 | B3: event_folder указан без финального номера набора | C3: да | D3: Референсная строка заполнена.
A4: 1 | B4: main_resource заменяет Adventure_GR_3 | C4: да | D4: Референсная строка заполнена.
A5: 1 | B5: pet classname указан и совпадает с финальной наградой | C5: да | D5: Референсная строка заполнена.
A6: 1 | B6: TrophyPet classname указан для collection_item и trophy | C6: да | D6: Референсная строка заполнена.
A7: 1 | B7: 7 reward milestones заполнены | C7: да | D7: Референсная строка заполнена.
A8: 1 | B8: reward strings не содержат старых Adventure_3_Sport_9 classname | C8: да | D8: Референсная строка заполнена.
A9: 1 | B9: quest_rule_window не содержит старую тему/сроки | C9: да | D9: Референсная строка заполнена.
A10: 1 | B10: экономика либо заполнена, либо явно наследуется | C10: да | D10: Референсная строка заполнена.
A11: 1 | B11: финальные XLSX будут разнесены по семействам и лист conf будет первым | C11: да | D11: Референсная строка заполнена.
A12: 2 | B12: new_prefix уникален и совпадает с будущими classname
A13: 2 | B13: event_folder указан без финального номера набора
A14: 2 | B14: main_resource заменяет Adventure_GR_3
A15: 2 | B15: pet classname указан и совпадает с финальной наградой
A16: 2 | B16: TrophyPet classname указан для collection_item и trophy
A17: 2 | B17: 7 reward milestones заполнены
A18: 2 | B18: reward strings не содержат старых Adventure_3_Sport_9 classname
A19: 2 | B19: quest_rule_window не содержит старую тему/сроки
A20: 2 | B20: экономика либо заполнена, либо явно наследуется
A21: 2 | B21: финальные XLSX будут разнесены по семействам и лист conf будет первым
A22: 3 | B22: new_prefix уникален и совпадает с будущими classname
A23: 3 | B23: event_folder указан без финального номера набора
... A121: 12 | B121: финальные XLSX будут разнесены по семействам и лист conf будет первым

Sheet README
A1: Adventure master brief
A3: Как работать
A4: 1. Заполни строку нужного pack на вкладке 01_Паки.
A5: 2. Проверь 02_Замены: первые три replace уже связаны формулами с 01_Паки.
A6: 3. На 03_Объекты заполни visible title/description/classname для pet, trophy, furniture, pots, boxes.
A7: 4. На 04_Квесты заполни тексты видимых квестов и правила, если они отличаются от reference.
A8: 5. На 05_Награды заполни 7 reward milestones. Это будущие tasks.0 - tasks.6 в rewards quest.
A9: 6. На 06_Экономика пиши только отличия. Пустое поле значит наследовать из Adventure_template.
A11: Цвета
A12: Жёлтый - желательно/обязательно заполнить для нового pack.
A13: Зелёный - опционально, можно оставить пустым и наследовать.
A14: Синий/серый - справочная или формульная зона.
... A28: Adventure output now includes quest_item.xlsx and mystery_box.xlsx when the pack has a new progress resource and reward boxes.

Sheet lists
A1: status | B1: yes_no | C1: entity_kind
A2: заполнить | B2: да | C2: main_resource
A3: готово для генерации | B3: нет | C3: pet
A4: сгенерировано | C4: collection_item
A5: проверено | C5: furniture
A6: не используется | C6: pot_multi
C7: pot_multi_magic
C8: trophy
C9: box_1
C10: box_2
C11: box_3
C12: other
